<mujoco model="untangle">
  <compiler angle="radian" meshdir="meshes/" autolimits="true"/>
  <option timestep="0.004" viscosity="0.002"/>
  <size njmax="500" nconmax="100"/>
  <visual>
    <scale framelength="0.2" framewidth="0.02"/>
  </visual>
  <statistic meansize="0.152835" extent="10" center="0 0 -0.445"/>
  <default class="main">
    <joint stiffness="0.5"/>
    <geom friction="0.0001 0.005 0.0001" solref="0.002 1"/>
    <default class="visual">
      <geom contype="0" conaffinity="0" group="2" solref="0.02 1"/>
    </default>
  </default>
  <custom>
    <text name="composite_" data="rope_"/>
  </custom>
  <asset>
    <texture type="2d" name="tex-light-wood" file="textures/light-wood.png"/>
    <texture type="2d" name="tex-dark-wood" file="textures/dark-wood.png"/>
    <texture type="2d" name="tex-metal" file="textures/metal.png"/>
    <texture type="2d" name="tex-cream-plaster" file="textures/cream-plaster.png"/>
    <texture type="2d" name="tex-grass" file="textures/grass.png"/>
    <material name="light-wood" texture="tex-light-wood" texuniform="true" texrepeat="15 15"/>
    <material name="dark-wood" texture="tex-dark-wood" texuniform="true" texrepeat="5 5"/>
    <material name="metal" texture="tex-metal" texuniform="true" texrepeat="5 5"/>
    <material name="cream-plaster" texture="tex-cream-plaster" texuniform="true" texrepeat="5 5"/>
    <material name="grass" texture="tex-grass" texuniform="true" texrepeat="0.2 0.2"/>
    <mesh name="PEDESTAL_ASSEMBLY" file="PEDESTAL_ASSEMBLY_simplified.stl"/>
    <mesh name="Drive56" file="Drive56_simplified.stl"/>
    <mesh name="MK4_MT" file="MK4_MT_simplified.stl"/>
    <mesh name="TORSO" file="TORSO_simplified.stl"/>
    <mesh name="MK4_LT" file="MK4_LT_simplified.stl"/>
    <mesh name="SHOULDER_BRACKET" file="SHOULDER_BRACKET_simplified.stl"/>
    <mesh name="PROXIMAL_TUBE" file="PROXIMAL_TUBE_simplified.stl"/>
    <mesh name="FOREARM_BRACKET" file="FOREARM_BRACKET_simplified.stl"/>
    <mesh name="A35_DRIVE" file="A35_DRIVE_simplified.stl"/>
    <mesh name="A35_BRACKET" file="A35_BRACKET_simplified.stl"/>
    <mesh name="PINCER_HOUSING2" file="PINCER_HOUSING2.stl"/>
    <mesh name="PINCER_FINGER" file="PINCER_FINGER.stl"/>
    <mesh name="soft_gripper_thin" file="soft_gripper_thin.stl"/>
    <mesh name="FINGER_PAD" file="FINGER_PAD.stl"/>
    <mesh name="FINGER_TIP" file="finger tip.stl" scale="0.001 0.001 0.001"/>
    <mesh name="d405_mount" file="d405_mount.stl"/>
  </asset>
  <worldbody>
    <light name="overhead1" pos="0 0 10" dir="0 0 -1" mode="trackcom"/>
    <body name="val_base">
      <body name="stand" pos="0 0 -0.26">
        <geom name="stand" size="0.25 0.25 0.17" type="box" rgba="0.3 0.3 0.1 1"/>
      </body>
      <body name="pedestal" quat="0.707141 -0.707073 0 0">
        <body name="drive56" pos="0 0 0.0891" quat="0.707141 -0.707073 0 0">
          <geom name="Drive56_mesh" type="mesh" rgba="0.2 0.2 0.2 1" mesh="Drive56"/>
          <body name="drive57" pos="0 0 -0.082642" quat="0.500048 0.5 0.5 0.499952">
            <joint name="joint56" pos="0 0 0" axis="0 -1 0" range="-6.2 6.2" damping="200" frictionloss="0.01"/>
            <geom name="drive57_mesh" type="mesh" rgba="0.2 0.2 0.2 1" mesh="MK4_MT"/>
            <body name="torso" pos="0 0 -0.04085" quat="0.5 0.5 -0.5 0.5">
              <joint name="joint57" pos="0 0 0" axis="-1 0 0" range="-1.5708 1.5708" damping="100" frictionloss="0.01"/>
              <geom name="torso" type="mesh" rgba="0.2 0.2 0.2 1" mesh="TORSO"/>
              <body name="drive1" pos="-0.092094 0 0.44399" quat="0.5 -0.5 0.5 -0.5">
                <geom name="drive1_mesh" type="mesh" rgba="0.2 0.2 0.2 1" mesh="MK4_MT"/>
              </body>
              <body name="drive41" pos="0.167906 0 0.44399" quat="0.5 -0.5 -0.5 0.5">
                <geom name="drive41_mesh" type="mesh" rgba="0.2 0.2 0.2 1" mesh="MK4_MT"/>
              </body>
              <body name="drive42" pos="-0.174736 0 0.44399" quat="0.5 -0.5 -0.5 -0.5">
                <joint name="joint41" pos="0 0 0" axis="0 1 0" range="-6.2 6.2" damping="20" frictionloss="1"/>
                <geom name="drive42_mesh" type="mesh" rgba="0.2 0.2 0.2 1" mesh="MK4_LT"/>
                <body name="leftshoulder" pos="0 0 -0.07526" quat="0.707107 0 0 -0.707107">
                  <joint name="joint42" pos="0 0 0" axis="0 0 1" range="-0.15 3.14159" damping="8" frictionloss="1"/>
                  <geom name="left_shoulder_bracket" type="mesh" rgba="0.2 0.2 0.2 1" mesh="SHOULDER_BRACKET"/>
                  <body name="drive43" pos="0 -0.1 0.07526" quat="0.707107 -0.707107 0 0">
                    <geom name="drive43_mesh" type="mesh" rgba="0.2 0.2 0.2 1" mesh="MK4_LT"/>
                  </body>
                  <body name="lefttube_and_drive" pos="0 -0.215888 0.07526" quat="-0.707107 -0.707107 0 0">
                    <joint name="joint43" pos="0 0 0" axis="0 0 -1" range="-6.2 6.2" damping="8" frictionloss="1"/>
                    <body name="lefttube" quat="0.707107 0 0.707107 0">
                      <geom name="lefttube_mesh" type="mesh" rgba="0.2 0.2 0.2 1" mesh="PROXIMAL_TUBE"/>
                    </body>
                    <body name="drive44" pos="0 0 0.0486304" quat="0.5 -0.5 -0.5 0.5">
                      <geom name="drive44_mesh" type="mesh" rgba="0.2 0.2 0.2 1" mesh="MK4_LT"/>
                    </body>
                    <body name="leftforearm" pos="0.06758 0 0.0486304" quat="0 -0.707107 0 0.707107">
                      <joint name="joint44" pos="0 0 0" axis="0 0 1" range="-4 1" damping="8" frictionloss="1"/>
                      <geom name="left_forearm_bracket" type="mesh" rgba="0.2 0.2 0.2 1" mesh="FOREARM_BRACKET"/>
                      <body name="drive45" pos="0 -0.17 0.05749" quat="0.707107 -0.707107 0 0">
                        <geom name="drive45_mesh" type="mesh" rgba="0.2 0.2 0.2 1" mesh="A35_DRIVE"/>
                      </body>
                      <body name="drive46" pos="0 -0.237262 0.05749" quat="0.707107 0 0.707107 0">
                        <joint name="joint45" pos="0 0 0" axis="0 1 0" range="-6.2 6.2" damping="0.4" frictionloss="0.01"/>
                        <geom name="drive46_mesh" type="mesh" rgba="0.2 0.2 0.2 1" mesh="A35_DRIVE"/>
                        <body name="leftwrist" pos="0 0 -0.0566728">
                          <joint name="joint46" pos="0 0 0" axis="0 0 -1" range="-1.5708 1.5708" damping="0.04" frictionloss="0.1"/>
                          <geom name="left_wrist_mesh" type="mesh" rgba="0.2 0.2 0.2 1" mesh="A35_BRACKET"/>
                          <body name="drive47" pos="0 -0.05 0.0566728" quat="0.707107 -0.707107 0 0">
                            <geom name="drive47_mesh" type="mesh" rgba="0.2 0.2 0.2 1" mesh="A35_DRIVE"/>
                          </body>
                          <body name="drive50" pos="0 -0.086 0.0566728" quat="0 0 0.707107 -0.707107">
                            <joint name="joint47" pos="0 0 0" axis="0 0 -1" range="-6.2 6.2" damping="0.08" frictionloss="0.1"/>
                            <geom name="drive47_housing_mesh" type="mesh" rgba="0.2 0.2 0.2 1" mesh="PINCER_HOUSING2"/>
                            <site name="left_tool" pos="0 0 0.181" size="0.001"/>
                            <body name="left_d405_mount" pos="-0.0215 0 0.031" quat="0.500048 0.5 -0.5 -0.499952">
                              <geom name="left_d405_mount" type="mesh" rgba="0.9 0.9 0.9 1" mesh="d405_mount"/>
                              <site name="left_hand_cam" pos="0 0.01 0.03" quat="-0.572867 0.819648 3.27427e-07 1.84758e-06" size="0.001"/>
                              <body name="left_d405" pos="0 0.01 0.03" quat="0.819648 0.572867 0 0">
                                <geom name="left_d405" size="0.021 0.021 0.0115" type="box"/>
                                <camera name="left_hand" pos="0 0 0"/>
                              </body>
                            </body>
                            <body name="leftgripper" pos="0 0.0135 0.068553" quat="0.593427 0.384568 -0.59337 -0.384531">
                              <joint name="leftgripper" pos="0 0 0" axis="0 0 1" range="-0.01 1" damping="0.01" frictionloss="0.01"/>
                              <geom name="leftgripper" type="mesh" group="1" friction="1 0.005 0.0001" rgba="0.8 0.8 0.8 1" mesh="soft_gripper_thin"/>
                              <body name="left_finger_pad" pos="0.0685 0.1 -0.0005" quat="1.01479e-06 0.764842 -0.644218 8.54745e-07">
                                <geom name="left_finger_pad" type="mesh" group="1" friction="1 0.005 0.0001" rgba="0.6 0.4 0.2 1" mesh="FINGER_TIP"/>
                              </body>
                            </body>
                            <body name="leftgripper2" pos="0 -0.0135 0.068553" quat="0.38504 0.593121 0.385003 0.593064">
                              <joint name="leftgripper2" pos="0 0 0" axis="0 0 1" range="-0.01 1" damping="0.01" frictionloss="0.01"/>
                              <geom name="leftgripper2" type="mesh" group="1" friction="1 0.005 0.0001" rgba="0.8 0.8 0.8 1" mesh="soft_gripper_thin"/>
                              <body name="left_finger_pad2" pos="0.0685 0.1 -0.0005" quat="1.01479e-06 0.764842 -0.644218 8.54745e-07">
                                <geom name="left_finger_pad2" type="mesh" group="1" friction="1 0.005 0.0001" rgba="0.6 0.4 0.2 1" mesh="FINGER_TIP"/>
                              </body>
                            </body>
                          </body>
                        </body>
                      </body>
                    </body>
                  </body>
                </body>
              </body>
              <body name="drive2" pos="0.250548 0 0.44399" quat="0.5 -0.5 0.5 0.5">
                <joint name="joint1" pos="0 0 0" axis="0 -1 0" range="-6.2 6.2" damping="20" frictionloss="1"/>
                <geom name="joint2_mesh" type="mesh" rgba="0.2 0.2 0.2 1" mesh="MK4_LT"/>
                <body name="rightshoulder" pos="0 0 -0.07526" quat="0.707107 0 0 0.707107">
                  <joint name="joint2" pos="0 0 0" axis="0 0 1" range="-3.14159 0.15" damping="8" frictionloss="1"/>
                  <geom name="right_shoulder_bracket" type="mesh" rgba="0.2 0.2 0.2 1" mesh="SHOULDER_BRACKET"/>
                  <body name="drive3" pos="0 -0.1 0.07526" quat="0.707107 -0.707107 0 0">
                    <geom name="joint3_mesh" type="mesh" rgba="0.2 0.2 0.2 1" mesh="MK4_LT"/>
                  </body>
                  <body name="righttube_and_drive" pos="0 -0.215888 0.07526" quat="0 0 -0.707107 0.707107">
                    <joint name="joint3" pos="0 0 0" axis="0 0 -1" range="-6.2 6.2" damping="8" frictionloss="1"/>
                    <body name="righttube" quat="0.707107 0 0.707107 0">
                      <geom name="righttube_mesh" type="mesh" rgba="0.2 0.2 0.2 1" mesh="PROXIMAL_TUBE"/>
                    </body>
                    <body name="drive4" pos="0 0 0.0486304" quat="0.5 -0.5 -0.5 0.5">
                      <geom name="drive4_mesh" type="mesh" rgba="0.2 0.2 0.2 1" mesh="MK4_LT"/>
                    </body>
                    <body name="rightforearm" pos="0.06758 0 0.0486304" quat="0.707107 0 -0.707107 0">
                      <joint name="joint4" pos="0 0 0" axis="0 0 -1" range="-4 1" damping="8" frictionloss="1"/>
                      <geom name="right_forearm_bracket" type="mesh" rgba="0.2 0.2 0.2 1" mesh="FOREARM_BRACKET"/>
                      <body name="drive5" pos="0 -0.17 0.05749" quat="0.707107 -0.707107 0 0">
                        <geom name="drive5_mesh" type="mesh" rgba="0.2 0.2 0.2 1" mesh="A35_DRIVE"/>
                      </body>
                      <body name="drive6" pos="0 -0.237262 0.05749" quat="0.707107 0 -0.707107 0">
                        <joint name="joint5" pos="0 0 0" axis="0 1 0" range="-6.2 6.2" damping="0.4" frictionloss="0.01"/>
                        <geom name="drive6_mesh" type="mesh" rgba="0.2 0.2 0.2 1" mesh="A35_DRIVE"/>
                        <body name="rightwrist" pos="0 0 -0.0566728">
                          <joint name="joint6" pos="0 0 0" axis="0 0 -1" range="-1.5708 1.5708" damping="0.04" frictionloss="0.1"/>
                          <geom name="rightwrist_mesh" type="mesh" rgba="0.2 0.2 0.2 1" mesh="A35_BRACKET"/>
                          <body name="drive7" pos="0 -0.05 0.0566728" quat="0.707107 -0.707107 0 0">
                            <geom name="drive7_mesh" type="mesh" rgba="0.2 0.2 0.2 1" mesh="A35_DRIVE"/>
                          </body>
                          <body name="drive10" pos="0 -0.086 0.0566728" quat="0.707107 0.707107 0 0">
                            <joint name="joint7" pos="0 0 0" axis="0 0 -1" range="-6.2 6.2" damping="0.08" frictionloss="0.1"/>
                            <geom name="drive7_housing_mesh" type="mesh" rgba="0.2 0.2 0.2 1" mesh="PINCER_HOUSING2"/>
                            <site name="right_tool" pos="0 0 0.181" size="0.001"/>
                            <body name="right_d405_mount" pos="-0.0215 0 0.031" quat="0.500048 0.5 -0.5 -0.499952">
                              <geom name="right_d405_mount" type="mesh" rgba="0.9 0.9 0.9 1" mesh="d405_mount"/>
                              <site name="right_hand_cam" pos="0.01 0 0.03" quat="2.63793e-05 -3.80829e-05 0.822049 0.569417" size="0.001"/>
                              <body name="right_d405" pos="0 0.01 0.03" quat="0.819648 0.572867 0 0">
                                <geom name="right_d405" size="0.021 0.021 0.0115" type="box"/>
                                <camera name="right_hand" pos="0 0 0"/>
                              </body>
                            </body>
                            <body name="rightgripper" pos="0 0.0135 0.068553" quat="0.593427 0.384568 -0.59337 -0.384531">
                              <joint name="rightgripper" pos="0 0 0" axis="0 0 1" range="-0.01 1" damping="0.01" frictionloss="0.01"/>
                              <geom name="rightgripper" type="mesh" group="1" friction="1 0.005 0.0001" rgba="0.9 0.9 0.9 1" mesh="soft_gripper_thin"/>
                              <body name="right_finger_pad" pos="0.0685 0.1 -0.0005" quat="1.01479e-06 0.764842 -0.644218 8.54745e-07">
                                <geom name="right_finger_pad" type="mesh" group="1" friction="1 0.005 0.0001" rgba="0.6 0.4 0.2 1" mesh="FINGER_TIP"/>
                              </body>
                            </body>
                            <body name="rightgripper2" pos="0 -0.0135 0.068553" quat="0.38504 0.593121 0.385003 0.593064">
                              <joint name="rightgripper2" pos="0 0 0" axis="0 0 1" range="-0.01 1" damping="0.01" frictionloss="0.01"/>
                              <geom name="rightgripper2" type="mesh" group="1" friction="1 0.005 0.0001" rgba="0.9 0.9 0.9 1" mesh="soft_gripper_thin"/>
                              <body name="right_finger_pad2" pos="0.0685 0.1 -0.0005" quat="1.01479e-06 0.764842 -0.644218 8.54745e-07">
                                <geom name="right_finger_pad2" type="mesh" group="1" friction="1 0.005 0.0001" rgba="0.6 0.4 0.2 1" mesh="FINGER_TIP"/>
                              </body>
                            </body>
                          </body>
                        </body>
                      </body>
                    </body>
                  </body>
                </body>
              </body>
            </body>
          </body>
        </body>
      </body>
    </body>
    <body name="obstacles" pos="-0.06 -0.02 -0.43" quat="0.999809 0.0149983 -0.000187488 0.0124983">
      <body name="walls">
        <geom name="right_wall" size="0.01 1 1" pos="0.8 0 1" type="box" rgba="0.5 0.1 0.1 0.1"/>
        <geom name="left_wall" size="0.01 1 1" pos="-0.46 0 1" type="box" rgba="0.5 0.1 0.1 0.1"/>
        <geom name="back_wall" size="1 0.01 1" pos="0 -0.26 1" type="box" rgba="0.5 0.1 0.1 0.1"/>
        <body name="front_wall" pos="-0.05 0.96 1">
          <geom name="front_wall" size="1 0.01 1" type="box" material="cream-plaster"/>
          <body name="outlet_bar" pos="0 -0.025 0.106">
            <geom name="outlet_bar" size="1 0.025 0.11" type="box" material="metal"/>
            <body name="goal" pos="0.05 -0.08 0">
              <geom name="goal" class="visual" size="0.1" pos="0 -0.04 0.02" rgba="0.8 0.5 0.8 0.5"/>
            </body>
          </body>
          <body name="tv" pos="0 -0.05 0.64">
            <geom name="tv" size="0.6 0.05 0.3" type="box" rgba="0 0 0 1"/>
          </body>
          <body name="attach" pos="0.52 -0.06 0.14">
            <geom name="attach" size="0.02 0.005 0.02" type="box" rgba="0.5 0 0 1"/>
          </body>
        </body>
      </body>
      <body name="table" pos="-0.31 0.715 0">
        <geom name="leg1" size="0.06 0.0275 0.35" pos="0.73 0.16 0.36" quat="0.923956 0 0 0.382499" type="box" material="metal"/>
        <geom name="leg2" size="0.06 0.0275 0.35" pos="-0.73 0.16 0.36" quat="0.923956 0 0 -0.382499" type="box" material="metal"/>
        <geom name="leg3" size="0.06 0.0275 0.35" pos="-0.73 -0.16 0.36" quat="0.923956 0 0 0.382499" type="box" material="metal"/>
        <geom name="leg4" size="0.06 0.0275 0.35" pos="0.73 -0.16 0.36" quat="0.923956 0 0 -0.382499" type="box" material="metal"/>
        <body name="top" pos="0 0 0.7">
          <geom name="top" size="0.79 0.255 0.038" type="box" rgba="0.35 0.45 0.5 1"/>
          <geom name="left_rim" size="0.038 0.255" pos="0.79 0 0" quat="0.707107 -0.707107 0 0" type="cylinder" rgba="0.35 0.45 0.5 1"/>
          <geom name="front_rim" size="0.038 0.79" pos="0 -0.255 0" quat="0.707107 0 0.707107 0" type="cylinder" rgba="0.35 0.45 0.5 1"/>
          <geom name="front_left_sphere" size="0.038" pos="0.79 -0.255 0" rgba="0.35 0.45 0.5 1"/>
        </body>
      </body>
    </body>
    <body name="floor" pos="0 0 -0.445">
      <geom name="floor" size="50 50 0.1" type="plane" material="cream-plaster"/>
    </body>
    <body name="cc_sphere">
      <joint name="cc_sphere" type="free" damping="0.1"/>
      <geom name="cc_sphere" size="0.005" rgba="1 1 1 0.1"/>
    </body>
    <body name="rope" pos="0.39 0.845 0.74" quat="0.763886 0.0382262 -0.643413 -0.0321975">
      <joint type="free" damping="1000"/>
      <body name="B_first">
        <joint name="J_first" pos="0 0 0" type="ball" group="3" stiffness="0.03" damping="0.05"/>
        <geom name="G0" size="0.007 0.0264583" pos="0.0264583 0 0" quat="0.707107 0 -0.707107 0" type="capsule" condim="1" friction="1 0.005 0.0001" solref="0.02 1" rgba="0.8 0.2 0.1 1"/>
        <site name="S_first" pos="0 0 0" group="3"/>
        <body name="B_1" pos="0.0529167 0 0">
          <joint name="J_1" pos="0 0 0" type="ball" group="3" stiffness="0.03" damping="0.05"/>
          <geom name="G1" size="0.007 0.0264583" pos="0.0264583 0 0" quat="0.707107 0 -0.707107 0" type="capsule" condim="1" friction="1 0.005 0.0001" solref="0.02 1" rgba="0.8 0.2 0.1 1"/>
          <body name="B_2" pos="0.0529167 0 0">
            <joint name="J_2" pos="0 0 0" type="ball" group="3" stiffness="0.03" damping="0.05"/>
            <geom name="G2" size="0.007 0.0264583" pos="0.0264583 0 0" quat="0.707107 0 -0.707107 0" type="capsule" condim="1" friction="1 0.005 0.0001" solref="0.02 1" rgba="0.8 0.2 0.1 1"/>
            <body name="B_3" pos="0.0529167 0 0">
              <joint name="J_3" pos="0 0 0" type="ball" group="3" stiffness="0.03" damping="0.05"/>
              <geom name="G3" size="0.007 0.0264583" pos="0.0264583 0 0" quat="0.707107 0 -0.707107 0" type="capsule" condim="1" friction="1 0.005 0.0001" solref="0.02 1" rgba="0.8 0.2 0.1 1"/>
              <body name="B_4" pos="0.0529166 0 0">
                <joint name="J_4" pos="0 0 0" type="ball" group="3" stiffness="0.03" damping="0.05"/>
                <geom name="G4" size="0.007 0.0264583" pos="0.0264583 0 0" quat="0.707107 0 -0.707107 0" type="capsule" condim="1" friction="1 0.005 0.0001" solref="0.02 1" rgba="0.8 0.2 0.1 1"/>
                <body name="B_5" pos="0.0529167 0 0">
                  <joint name="J_5" pos="0 0 0" type="ball" group="3" stiffness="0.03" damping="0.05"/>
                  <geom name="G5" size="0.007 0.0264583" pos="0.0264583 0 0" quat="0.707107 0 -0.707107 0" type="capsule" condim="1" friction="1 0.005 0.0001" solref="0.02 1" rgba="0.8 0.2 0.1 1"/>
                  <body name="B_6" pos="0.0529167 0 0">
                    <joint name="J_6" pos="0 0 0" type="ball" group="3" stiffness="0.03" damping="0.05"/>
                    <geom name="G6" size="0.007 0.0264583" pos="0.0264583 0 0" quat="0.707107 0 -0.707107 0" type="capsule" condim="1" friction="1 0.005 0.0001" solref="0.02 1" rgba="0.8 0.2 0.1 1"/>
                    <body name="B_7" pos="0.0529167 0 0">
                      <joint name="J_7" pos="0 0 0" type="ball" group="3" stiffness="0.03" damping="0.05"/>
                      <geom name="G7" size="0.007 0.0264583" pos="0.0264583 0 0" quat="0.707107 0 -0.707107 0" type="capsule" condim="1" friction="1 0.005 0.0001" solref="0.02 1" rgba="0.8 0.2 0.1 1"/>
                      <body name="B_8" pos="0.0529166 0 0">
                        <joint name="J_8" pos="0 0 0" type="ball" group="3" stiffness="0.03" damping="0.05"/>
                        <geom name="G8" size="0.007 0.0264583" pos="0.0264583 0 0" quat="0.707107 0 -0.707107 0" type="capsule" condim="1" friction="1 0.005 0.0001" solref="0.02 1" rgba="0.8 0.2 0.1 1"/>
                        <body name="B_9" pos="0.0529166 0 0">
                          <joint name="J_9" pos="0 0 0" type="ball" group="3" stiffness="0.03" damping="0.05"/>
                          <geom name="G9" size="0.007 0.0264583" pos="0.0264583 0 0" quat="0.707107 0 -0.707107 0" type="capsule" condim="1" friction="1 0.005 0.0001" solref="0.02 1" rgba="0.8 0.2 0.1 1"/>
                          <body name="B_10" pos="0.0529167 0 0">
                            <joint name="J_10" pos="0 0 0" type="ball" group="3" stiffness="0.03" damping="0.05"/>
                            <geom name="G10" size="0.007 0.0264584" pos="0.0264584 0 0" quat="0.707107 0 -0.707107 0" type="capsule" condim="1" friction="1 0.005 0.0001" solref="0.02 1" rgba="0.8 0.2 0.1 1"/>
                            <body name="B_11" pos="0.0529166 0 0">
                              <joint name="J_11" pos="0 0 0" type="ball" group="3" stiffness="0.03" damping="0.05"/>
                              <geom name="G11" size="0.007 0.0264583" pos="0.0264583 0 0" quat="0.707107 0 -0.707107 0" type="capsule" condim="1" friction="1 0.005 0.0001" solref="0.02 1" rgba="0.8 0.2 0.1 1"/>
                              <body name="B_12" pos="0.0529167 0 0">
                                <joint name="J_12" pos="0 0 0" type="ball" group="3" stiffness="0.03" damping="0.05"/>
                                <geom name="G12" size="0.007 0.0264584" pos="0.0264584 0 0" quat="0.707107 0 -0.707107 0" type="capsule" condim="1" friction="1 0.005 0.0001" solref="0.02 1" rgba="0.8 0.2 0.1 1"/>
                                <body name="B_13" pos="0.0529166 0 0">
                                  <joint name="J_13" pos="0 0 0" type="ball" group="3" stiffness="0.03" damping="0.05"/>
                                  <geom name="G13" size="0.007 0.0264583" pos="0.0264583 0 0" quat="0.707107 0 -0.707107 0" type="capsule" condim="1" friction="1 0.005 0.0001" solref="0.02 1" rgba="0.8 0.2 0.1 1"/>
                                  <body name="B_14" pos="0.0529166 0 0">
                                    <joint name="J_14" pos="0 0 0" type="ball" group="3" stiffness="0.03" damping="0.05"/>
                                    <geom name="G14" size="0.007 0.0264583" pos="0.0264583 0 0" quat="0.707107 0 -0.707107 0" type="capsule" condim="1" friction="1 0.005 0.0001" solref="0.02 1" rgba="0.8 0.2 0.1 1"/>
                                    <body name="B_15" pos="0.0529167 0 0">
                                      <joint name="J_15" pos="0 0 0" type="ball" group="3" stiffness="0.03" damping="0.05"/>
                                      <geom name="G15" size="0.007 0.0264584" pos="0.0264584 0 0" quat="0.707107 0 -0.707107 0" type="capsule" condim="1" friction="1 0.005 0.0001" solref="0.02 1" rgba="0.8 0.2 0.1 1"/>
                                      <body name="B_16" pos="0.0529166 0 0">
                                        <joint name="J_16" pos="0 0 0" type="ball" group="3" stiffness="0.03" damping="0.05"/>
                                        <geom name="G16" size="0.007 0.0264583" pos="0.0264583 0 0" quat="0.707107 0 -0.707107 0" type="capsule" condim="1" friction="1 0.005 0.0001" solref="0.02 1" rgba="0.8 0.2 0.1 1"/>
                                        <body name="B_17" pos="0.0529166 0 0">
                                          <joint name="J_17" pos="0 0 0" type="ball" group="3" stiffness="0.03" damping="0.05"/>
                                          <geom name="G17" size="0.007 0.0264583" pos="0.0264583 0 0" quat="0.707107 0 -0.707107 0" type="capsule" condim="1" friction="1 0.005 0.0001" solref="0.02 1" rgba="0.8 0.2 0.1 1"/>
                                          <body name="B_18" pos="0.0529166 0 0">
                                            <joint name="J_18" pos="0 0 0" type="ball" group="3" stiffness="0.03" damping="0.05"/>
                                            <geom name="G18" size="0.007 0.0264583" pos="0.0264583 0 0" quat="0.707107 0 -0.707107 0" type="capsule" condim="1" friction="1 0.005 0.0001" solref="0.02 1" rgba="0.8 0.2 0.1 1"/>
                                            <body name="B_19" pos="0.0529166 0 0">
                                              <joint name="J_19" pos="0 0 0" type="ball" group="3" stiffness="0.03" damping="0.05"/>
                                              <geom name="G19" size="0.007 0.0264583" pos="0.0264583 0 0" quat="0.707107 0 -0.707107 0" type="capsule" condim="1" friction="1 0.005 0.0001" solref="0.02 1" rgba="0.8 0.2 0.1 1"/>
                                              <body name="B_20" pos="0.0529168 0 0">
                                                <joint name="J_20" pos="0 0 0" type="ball" group="3" stiffness="0.03" damping="0.05"/>
                                                <geom name="G20" size="0.007 0.0264584" pos="0.0264584 0 0" quat="0.707107 0 -0.707107 0" type="capsule" condim="1" friction="1 0.005 0.0001" solref="0.02 1" rgba="0.8 0.2 0.1 1"/>
                                                <body name="B_21" pos="0.0529166 0 0">
                                                  <joint name="J_21" pos="0 0 0" type="ball" group="3" stiffness="0.03" damping="0.05"/>
                                                  <geom name="G21" size="0.007 0.0264583" pos="0.0264583 0 0" quat="0.707107 0 -0.707107 0" type="capsule" condim="1" friction="1 0.005 0.0001" solref="0.02 1" rgba="0.8 0.2 0.1 1"/>
                                                  <body name="B_22" pos="0.0529166 0 0">
                                                    <joint name="J_22" pos="0 0 0" type="ball" group="3" stiffness="0.03" damping="0.05"/>
                                                    <geom name="G22" size="0.007 0.0264583" pos="0.0264583 0 0" quat="0.707107 0 -0.707107 0" type="capsule" condim="1" friction="1 0.005 0.0001" solref="0.02 1" rgba="0.8 0.2 0.1 1"/>
                                                    <body name="B_last" pos="0.0529166 0 0">
                                                      <joint name="J_last" pos="0 0 0" type="ball" group="3" stiffness="0.03" damping="0.05"/>
                                                      <geom name="G23" size="0.007 0.0264583" pos="0.0264583 0 0" quat="0.707107 0 -0.707107 0" type="capsule" condim="1" friction="1 0.005 0.0001" solref="0.02 1" rgba="0.8 0.2 0.1 1"/>
                                                      <site name="S_last" pos="0.0529166 0 0" group="3"/>
                                                    </body>
                                                  </body>
                                                </body>
                                              </body>
                                            </body>
                                          </body>
                                        </body>
                                      </body>
                                    </body>
                                  </body>
                                </body>
                              </body>
                            </body>
                          </body>
                        </body>
                      </body>
                    </body>
                  </body>
                </body>
              </body>
            </body>
          </body>
        </body>
      </body>
    </body>
    <body name="mycamera">
      <camera name="mycamera" pos="-0.3 -0.5 1.4" quat="0.900089 0.392529 -0.0755941 -0.173341"/>
    </body>
  </worldbody>
  <contact>
    <exclude body1="B_first" body2="B_1"/>
    <exclude body1="B_1" body2="B_2"/>
    <exclude body1="B_2" body2="B_3"/>
    <exclude body1="B_3" body2="B_4"/>
    <exclude body1="B_4" body2="B_5"/>
    <exclude body1="B_5" body2="B_6"/>
    <exclude body1="B_6" body2="B_7"/>
    <exclude body1="B_7" body2="B_8"/>
    <exclude body1="B_8" body2="B_9"/>
    <exclude body1="B_9" body2="B_10"/>
    <exclude body1="B_10" body2="B_11"/>
    <exclude body1="B_11" body2="B_12"/>
    <exclude body1="B_12" body2="B_13"/>
    <exclude body1="B_13" body2="B_14"/>
    <exclude body1="B_14" body2="B_15"/>
    <exclude body1="B_15" body2="B_16"/>
    <exclude body1="B_16" body2="B_17"/>
    <exclude body1="B_17" body2="B_18"/>
    <exclude body1="B_18" body2="B_19"/>
    <exclude body1="B_19" body2="B_20"/>
    <exclude body1="B_20" body2="B_21"/>
    <exclude body1="B_21" body2="B_22"/>
    <exclude body1="B_22" body2="B_last"/>
  </contact>
  <equality>
    <joint name="left_mimic" joint1="leftgripper" joint2="leftgripper2" polycoef="0 1 0 0 0" solref="0.01 1"/>
    <joint name="right_mimic" joint1="rightgripper" joint2="rightgripper2" polycoef="0 1 0 0 0" solref="0.01 1"/>
    <connect name="left" body1="drive50" body2="B_first" anchor="0 0 0.165" active="false" solref="0.04 1"/>
    <connect name="right" body1="drive10" body2="B_first" anchor="0 0 0.165" active="false" solref="0.04 1"/>
    <connect name="attach" body1="attach" body2="B_first" anchor="0 0 0" solref="0.01 1"/>
    <connect name="B_0" body1="world" body2="B_first" anchor="0 0 0" active="false" solref="0.1 1"/>
    <connect name="B_1" body1="world" body2="B_1" anchor="0 0 0" active="false" solref="0.1 1"/>
    <connect name="B_2" body1="world" body2="B_2" anchor="0 0 0" active="false" solref="0.1 1"/>
    <connect name="B_3" body1="world" body2="B_3" anchor="0 0 0" active="false" solref="0.1 1"/>
    <connect name="B_4" body1="world" body2="B_4" anchor="0 0 0" active="false" solref="0.1 1"/>
    <connect name="B_5" body1="world" body2="B_5" anchor="0 0 0" active="false" solref="0.1 1"/>
    <connect name="B_6" body1="world" body2="B_6" anchor="0 0 0" active="false" solref="0.1 1"/>
    <connect name="B_7" body1="world" body2="B_7" anchor="0 0 0" active="false" solref="0.1 1"/>
    <connect name="B_8" body1="world" body2="B_8" anchor="0 0 0" active="false" solref="0.1 1"/>
    <connect name="B_9" body1="world" body2="B_9" anchor="0 0 0" active="false" solref="0.1 1"/>
    <connect name="B_10" body1="world" body2="B_10" anchor="0 0 0" active="false" solref="0.1 1"/>
    <connect name="B_11" body1="world" body2="B_11" anchor="0 0 0" active="false" solref="0.1 1"/>
    <connect name="B_12" body1="world" body2="B_12" anchor="0 0 0" active="false" solref="0.1 1"/>
    <connect name="B_13" body1="world" body2="B_13" anchor="0 0 0" active="false" solref="0.1 1"/>
    <connect name="B_14" body1="world" body2="B_14" anchor="0 0 0" active="false" solref="0.1 1"/>
    <connect name="B_15" body1="world" body2="B_15" anchor="0 0 0" active="false" solref="0.1 1"/>
    <connect name="B_16" body1="world" body2="B_16" anchor="0 0 0" active="false" solref="0.1 1"/>
    <connect name="B_17" body1="world" body2="B_17" anchor="0 0 0" active="false" solref="0.1 1"/>
    <connect name="B_18" body1="world" body2="B_18" anchor="0 0 0" active="false" solref="0.1 1"/>
    <connect name="B_19" body1="world" body2="B_19" anchor="0 0 0" active="false" solref="0.1 1"/>
    <connect name="B_20" body1="world" body2="B_20" anchor="0 0 0" active="false" solref="0.1 1"/>
    <connect name="B_21" body1="world" body2="B_21" anchor="0 0 0" active="false" solref="0.1 1"/>
    <connect name="B_22" body1="world" body2="B_22" anchor="0 0 0" active="false" solref="0.1 1"/>
    <connect name="B_23" body1="world" body2="B_last" anchor="0 0 0" active="false" solref="0.1 1"/>
    <connect name="B_24" body1="world" body2="B_last" anchor="0 0 0" active="false" solref="0.1 1"/>
  </equality>
  <actuator>
    <general name="joint56_vel" joint="joint56" ctrlrange="-0.45 0.45" forcerange="-50 50" actrange="-6.2 6.2" dyntype="integrator" biastype="affine" gainprm="5000 0 0 0 0 0 0 0 0 0" biasprm="0 -5000 0 0 0 0 0 0 0 0"/>
    <general name="joint57_vel" joint="joint57" ctrlrange="-0.45 0.45" forcerange="-55 55" actrange="-1.5708 1.5708" dyntype="integrator" biastype="affine" gainprm="20000 0 0 0 0 0 0 0 0 0" biasprm="0 -20000 0 0 0 0 0 0 0 0"/>
    <general name="joint41_vel" joint="joint41" ctrlrange="-0.45 0.45" forcerange="-15 15" actrange="-6.2 6.2" dyntype="integrator" biastype="affine" gainprm="10000 0 0 0 0 0 0 0 0 0" biasprm="0 -10000 0 0 0 0 0 0 0 0"/>
    <general name="joint42_vel" joint="joint42" ctrlrange="-0.45 0.45" forcerange="-15 15" actrange="-0.15 3.14159" dyntype="integrator" biastype="affine" gainprm="5000 0 0 0 0 0 0 0 0 0" biasprm="0 -5000 0 0 0 0 0 0 0 0"/>
    <general name="joint43_vel" joint="joint43" ctrlrange="-0.45 0.45" forcerange="-10 10" actrange="-6.2 6.2" dyntype="integrator" biastype="affine" gainprm="5000 0 0 0 0 0 0 0 0 0" biasprm="0 -5000 0 0 0 0 0 0 0 0"/>
    <general name="joint44_vel" joint="joint44" ctrlrange="-0.45 0.45" forcerange="-10 10" actrange="-4 1" dyntype="integrator" biastype="affine" gainprm="1000 0 0 0 0 0 0 0 0 0" biasprm="0 -1000 0 0 0 0 0 0 0 0"/>
    <general name="joint45_vel" joint="joint45" ctrlrange="-2 2" forcerange="-8 8" actrange="-6.2 6.2" dyntype="integrator" biastype="affine" gainprm="100 0 0 0 0 0 0 0 0 0" biasprm="0 -100 0 0 0 0 0 0 0 0"/>
    <general name="joint46_vel" joint="joint46" ctrlrange="-2 2" forcerange="-4 4" actrange="-1.5708 1.5708" dyntype="integrator" biastype="affine" gainprm="500 0 0 0 0 0 0 0 0 0" biasprm="0 -500 0 0 0 0 0 0 0 0"/>
    <general name="joint47_vel" joint="joint47" ctrlrange="-3.1 3.1" forcerange="-3 3" actrange="-6.2 6.2" dyntype="integrator" biastype="affine" gainprm="50 0 0 0 0 0 0 0 0 0" biasprm="0 -50 0 0 0 0 0 0 0 0"/>
    <general name="leftgripper_vel" joint="leftgripper" ctrlrange="-0.5 0.5" forcerange="-1 1" actrange="-0.01 1" dyntype="integrator" biastype="affine" gainprm="35 0 0 0 0 0 0 0 0 0" biasprm="0 -35 0 0 0 0 0 0 0 0"/>
    <general name="joint1_vel" joint="joint1" ctrlrange="-0.45 0.45" forcerange="-15 15" actrange="-6.2 6.2" dyntype="integrator" biastype="affine" gainprm="10000 0 0 0 0 0 0 0 0 0" biasprm="0 -10000 0 0 0 0 0 0 0 0"/>
    <general name="joint2_vel" joint="joint2" ctrlrange="-0.45 0.45" forcerange="-15 15" actrange="-3.14159 0.15" dyntype="integrator" biastype="affine" gainprm="5000 0 0 0 0 0 0 0 0 0" biasprm="0 -5000 0 0 0 0 0 0 0 0"/>
    <general name="joint3_vel" joint="joint3" ctrlrange="-0.45 0.45" forcerange="-10 10" actrange="-6.2 6.2" dyntype="integrator" biastype="affine" gainprm="5000 0 0 0 0 0 0 0 0 0" biasprm="0 -5000 0 0 0 0 0 0 0 0"/>
    <general name="joint4_vel" joint="joint4" ctrlrange="-0.45 0.45" forcerange="-8 8" actrange="-4 1" dyntype="integrator" biastype="affine" gainprm="1000 0 0 0 0 0 0 0 0 0" biasprm="0 -1000 0 0 0 0 0 0 0 0"/>
    <general name="joint5_vel" joint="joint5" ctrlrange="-2 2" forcerange="-8 8" actrange="-6.2 6.2" dyntype="integrator" biastype="affine" gainprm="100 0 0 0 0 0 0 0 0 0" biasprm="0 -100 0 0 0 0 0 0 0 0"/>
    <general name="joint6_vel" joint="joint6" ctrlrange="-2 2" forcerange="-4 4" actrange="-1.5708 1.5708" dyntype="integrator" biastype="affine" gainprm="500 0 0 0 0 0 0 0 0 0" biasprm="0 -500 0 0 0 0 0 0 0 0"/>
    <general name="joint7_vel" joint="joint7" ctrlrange="-3.1 3.1" forcerange="-3 3" actrange="-6.2 6.2" dyntype="integrator" biastype="affine" gainprm="50 0 0 0 0 0 0 0 0 0" biasprm="0 -50 0 0 0 0 0 0 0 0"/>
    <general name="rightgripper_vel" joint="rightgripper" ctrlrange="-0.5 0.5" forcerange="-1 1" actrange="-0.01 1" dyntype="integrator" biastype="affine" gainprm="35 0 0 0 0 0 0 0 0 0" biasprm="0 -35 0 0 0 0 0 0 0 0"/>
  </actuator>
</mujoco>
