<mujoco model="threading_scene">
    <default>
        <joint stiffness="0.5" />
        <geom friction="0.01" />
        <default class="visual">
            
            <geom contype="0" conaffinity="0" group="2" />
        </default>
    </default>
    <worldbody>
        
        <body name="mycamera">
            <camera mode="fixed" name="mycamera" xyaxes="1.0 0.4 0 0.0 1.0 0.5" pos="0.5 -0.1 1.7" />
        </body>
        <light name="top" pos="-1 0 105" mode="trackcom" />
    </worldbody>
    <equality>
        <weld body1="drive50" body2="B_first" name="left" relpose="0 0 0.17 1 0 0 0" active="false" solref="0.04 1" torquescale="0.2" />
        <weld body1="drive10" body2="B_first" name="right" relpose="0 0 0.17 1 0 0 0" active="false" solref="0.04 1" torquescale="0.2" />

        <connect body1="attach1" body2="B_first" name="attach1" anchor="0 -0.03 0" active="false" solref="0.03 1" />
        <connect body1="attach2" body2="B_first" name="attach2" anchor="0 0.03 0" active="false" solref="0.03 1" />
        
        <connect body1="loop1" body2="B_first" name="attach_loop1" anchor="0 0 0.06" active="false" solref="0.03 1" />
        <connect body1="loop2" body2="B_first" name="attach_loop2" anchor="0 0 0.06" active="false" solref="0.03 1" />
        <connect body1="loop3" body2="B_first" name="attach_loop3" anchor="0 0 0.06" active="false" solref="0.03 1" />
    </equality>
<asset>
        <texture file="textures/light-wood.png" type="2d" name="tex-light-wood" />
        <texture file="textures/dark-wood.png" type="2d" name="tex-dark-wood" />
        <texture file="textures/metal.png" type="2d" name="tex-metal" />
        <texture file="textures/cream-plaster.png" type="2d" name="tex-cream-plaster" />
        <texture file="textures/grass.png" type="2d" name="tex-grass" />
        <material name="light-wood" reflectance="0" texrepeat="15 15" texture="tex-light-wood" texuniform="true" />
        <material name="dark-wood" reflectance="0" texrepeat="5 5" texture="tex-dark-wood" texuniform="true" />
        <material name="metal" reflectance="0" texrepeat="5 5" texture="tex-metal" texuniform="true" />
        <material name="cream-plaster" reflectance="0" texrepeat="5 5" texture="tex-cream-plaster" texuniform="true" />
        <material name="grass" reflectance="0" texrepeat="0.2 0.2" texture="tex-grass" texuniform="true" />
    </asset>
<compiler angle="radian" meshdir="meshes/" inertiafromgeom="true" />
    <option viscosity="1" timestep="0.004" />
    <default>
        <geom solref="0.002 1" />
    </default>
    <size njmax="500" nconmax="100" />
    <visual>
        <scale framewidth="0.02" framelength="0.2" />
    </visual>
    <asset>
        <mesh name="PEDESTAL_ASSEMBLY" file="PEDESTAL_ASSEMBLY_simplified.stl" />
        <mesh name="Drive56" file="Drive56_simplified.stl" />
        <mesh name="MK4_MT" file="MK4_MT_simplified.stl" />
        <mesh name="TORSO" file="TORSO_simplified.stl" />
        <mesh name="MK4_LT" file="MK4_LT_simplified.stl" />
        <mesh name="SHOULDER_BRACKET" file="SHOULDER_BRACKET_simplified.stl" />
        <mesh name="PROXIMAL_TUBE" file="PROXIMAL_TUBE_simplified.stl" />
        <mesh name="FOREARM_BRACKET" file="FOREARM_BRACKET_simplified.stl" />
        <mesh name="A35_DRIVE" file="A35_DRIVE_simplified.stl" />
        <mesh name="A35_BRACKET" file="A35_BRACKET_simplified.stl" />
        <mesh name="PINCER_HOUSING2" file="PINCER_HOUSING2.stl" />
        <mesh name="PINCER_FINGER" file="PINCER_FINGER.stl" />
        <mesh name="soft_gripper_thin" file="soft_gripper_thin.stl" />
        <mesh name="FINGER_PAD" file="FINGER_PAD.stl" />
        <mesh name="d405_mount" file="d405_mount.stl" />
    </asset>
    <worldbody>
        <body pos="0 0 0" name="val_base">
            <body pos="0 0 -0.26" euler="0 0 0" name="stand">
                <geom type="box" name="stand" size="0.25 0.25 0.17" rgba="0.3 0.3 0.1 1" />
            </body>
            <body name="pedestal" pos="0 0 0" euler="-1.5707 0 0">
                <body pos="0 0 0.0891" euler="-1.5707 0 0" name="drive56">
                    <geom type="mesh" mesh="Drive56" name="Drive56_mesh" rgba="0.2 0.2 0.2 1" />
                    <body name="drive57" pos="0 0 -0.082642" euler="1.5707 1.5707 0">
                        <joint name="joint56" type="hinge" pos="0 0 0" axis="0 -1 0" limited="true" range="-6.2 6.2" damping="200" frictionloss="0.01" />
                        <geom type="mesh" mesh="MK4_MT" name="drive57_mesh" rgba="0.2 0.2 0.2 1" />
                        <body name="torso" pos="0 0 -0.04085" quat="0.5 0.5 -0.5 0.5">
                            <joint name="joint57" type="hinge" pos="0 0 0" axis="-1 0 0" limited="true" range="-1.5708 1.5708" damping="100" frictionloss="0.01" />
                            <geom type="mesh" mesh="TORSO" name="torso" rgba="0.2 0.2 0.2 1" />
                            <body pos="-0.092094 0 0.44399" quat="0.5 -0.5 0.5 -0.5" name="drive1">
                                <geom type="mesh" mesh="MK4_MT" name="drive1_mesh" rgba="0.2 0.2 0.2 1" />
                            </body>
                            <body pos="0.167906 0 0.44399" quat="0.5 -0.5 -0.5 0.5" name="drive41">
                                <geom type="mesh" mesh="MK4_MT" name="drive41_mesh" rgba="0.2 0.2 0.2 1" />
                            </body>
                            <body name="drive42" pos="-0.174736 0 0.44399" quat="0.5 -0.5 -0.5 -0.5">
                                <joint name="joint41" type="hinge" pos="0 0 0" axis="0 1 0" limited="true" range="-6.2 6.2" damping="20" frictionloss="1" />
                                <geom type="mesh" mesh="MK4_LT" name="drive42_mesh" rgba="0.2 0.2 0.2 1" />
                                <body name="leftshoulder" pos="0 0 -0.07526" quat="0.707107 0 0 -0.707107">
                                    <joint name="joint42" type="hinge" pos="0 0 0" axis="0 0 1" limited="true" range="-0.15 3.14159" damping="8" frictionloss="1" />
                                    <geom type="mesh" mesh="SHOULDER_BRACKET" name="left_shoulder_bracket" rgba="0.2 0.2 0.2 1" />
                                    <body pos="0 -0.1 0.07526" quat="0.707107 -0.707107 0 0" name="drive43">
                                        <geom type="mesh" mesh="MK4_LT" name="drive43_mesh" rgba="0.2 0.2 0.2 1" />
                                    </body>
                                    <body name="lefttube_and_drive" pos="0 -0.215888 0.07526" quat="-0.707107 -0.707107 0 0">
                                        <joint name="joint43" type="hinge" pos="0 0 0" axis="0 0 -1" limited="true" range="-6.2 6.2" damping="8" frictionloss="1" />
                                        <body quat="0.707107 0 0.707107 0" name="lefttube">
                                            <geom type="mesh" mesh="PROXIMAL_TUBE" name="lefttube_mesh" rgba="0.2 0.2 0.2 1" />
                                        </body>
                                        <body pos="0 0 0.0486304" quat="0.5 -0.5 -0.5 0.5" name="drive44">
                                            <geom type="mesh" mesh="MK4_LT" name="drive44_mesh" rgba="0.2 0.2 0.2 1" />
                                        </body>
                                        <body name="leftforearm" pos="0.06758 0 0.0486304" quat="0 -0.707107 0 0.707107">
                                            <joint name="joint44" type="hinge" pos="0 0 0" axis="0 0 1" limited="true" range="-3.14159 1.0" damping="8" frictionloss="1" />
                                            <geom type="mesh" mesh="FOREARM_BRACKET" name="left_forearm_bracket" rgba="0.2 0.2 0.2 1" />
                                            <body pos="0 -0.17 0.05749" quat="0.707107 -0.707107 0 0" name="drive45">
                                                <geom type="mesh" mesh="A35_DRIVE" name="drive45_mesh" rgba="0.2 0.2 0.2 1" />
                                            </body>
                                            <body name="drive46" pos="0 -0.237262 0.05749" quat="0.707107 0 0.707107 0">
                                                <joint name="joint45" type="hinge" pos="0 0 0" axis="0 1 0" limited="true" range="-6.2 6.2" damping="0.4" frictionloss="0.01" />
                                                <geom type="mesh" mesh="A35_DRIVE" name="drive46_mesh" rgba="0.2 0.2 0.2 1" />
                                                <body name="leftwrist" pos="0 0 -0.0566728">
                                                    <joint name="joint46" type="hinge" pos="0 0 0" axis="0 0 -1" limited="true" range="-1.5708 1.5708" damping="0.04" frictionloss="0.1" />
                                                    <geom type="mesh" mesh="A35_BRACKET" name="left_wrist_mesh" rgba="0.2 0.2 0.2 1" />
                                                    <body pos="0 -0.05 0.0566728" quat="0.707107 -0.707107 0 0" name="drive47">
                                                        <geom type="mesh" mesh="A35_DRIVE" name="drive47_mesh" rgba="0.2 0.2 0.2 1" />
                                                    </body>
                                                    <body name="drive50" pos="0 -0.086 0.0566728" quat="0 0 0.707107 -0.707107">
                                                        <joint name="joint47" type="hinge" pos="0 0 0" axis="0 0 -1" limited="true" range="-6.2 6.2" damping="0.08" frictionloss="0.1" />
                                                        <geom type="mesh" mesh="PINCER_HOUSING2" name="drive47_housing_mesh" rgba="0.2 0.2 0.2 1" />
                                                        <site name="left_tool" pos="0 0 0.181" size="0.001" />
                                                        <body name="left_d405_mount" pos="-0.0215 0 0.031" euler="1.5707 -1.5707 0">
                                                            <geom type="mesh" mesh="d405_mount" name="left_d405_mount" rgba="0.9 0.9 0.9 1" />
                                                            <body name="left_d405" euler="1.22 0 0" pos="0 0.01 0.03">
                                                                <camera mode="fixed" name="left_hand" />
                                                                <geom name="left_d405" type="box" size="0.021 0.021 0.0115" />
                                                            </body>
                                                            
                                                            <site name="left_hand_cam" euler="1.22 3.14159 3.14159" pos="0 0.01 0.03" size="0.001" />
                                                        </body>
                                                        <body name="leftgripper" pos="0 0.0135 0.068553" euler="1.15 -1.5707 0">
                                                            <joint name="leftgripper" type="hinge" axis="0 0 1" limited="true" range="-0.01 1" damping="0.01" frictionloss="0.01" />
                                                            <geom type="mesh" mesh="soft_gripper_thin" name="leftgripper" friction="0.00001" rgba="0.8 0.8 0.8 1" group="1" />
                                                            <body name="left_finger_pad" pos="0.052 0.1 0">
                                                                <geom type="mesh" mesh="FINGER_PAD" name="left_finger_pad" rgba="0.6 0.4 0.2 1" group="1" />
                                                            </body>
                                                        </body>
                                                        <body name="leftgripper2" pos="0 -0.0135 0.068553" euler="1.99 1.5707 0">
                                                            <joint name="leftgripper2" type="hinge" axis="0 0 1" limited="true" range="-0.01 1" damping="0.01" frictionloss="0.01" />
                                                            <geom type="mesh" mesh="soft_gripper_thin" name="leftgripper2" friction="0.00001" rgba="0.8 0.8 0.8 1" group="1" />
                                                            <body name="left_finger_pad2" pos="0.052 0.1 0">
                                                                <geom type="mesh" mesh="FINGER_PAD" name="left_finger_pad2" rgba="0.6 0.4 0.2 1" group="1" />
                                                            </body>
                                                        </body>
                                                    </body>
                                                </body>
                                            </body>
                                        </body>
                                    </body>
                                </body>
                            </body>
                            <body name="drive2" pos="0.250548 0 0.44399" quat="0.5 -0.5 0.5 0.5">
                                <joint name="joint1" type="hinge" pos="0 0 0" axis="0 -1 0" limited="true" range="-6.2 6.2" damping="20" frictionloss="1" />
                                <geom type="mesh" mesh="MK4_LT" name="joint2_mesh" rgba="0.2 0.2 0.2 1" />
                                <body name="rightshoulder" pos="0 0 -0.07526" quat="0.707107 0 0 0.707107">
                                    <joint name="joint2" type="hinge" pos="0 0 0" axis="0 0 1" limited="true" range="-3.14159 0.15" damping="8" frictionloss="1" />
                                    <geom type="mesh" mesh="SHOULDER_BRACKET" name="right_shoulder_bracket" rgba="0.2 0.2 0.2 1" />
                                    <body pos="0 -0.1 0.07526" quat="0.707107 -0.707107 0 0" name="drive3">
                                        <geom type="mesh" mesh="MK4_LT" name="joint3_mesh" rgba="0.2 0.2 0.2 1" />
                                    </body>
                                    <body name="righttube_and_drive" pos="0 -0.215888 0.07526" quat="0 0 -0.707107 0.707107">
                                        <joint name="joint3" type="hinge" pos="0 0 0" axis="0 0 -1" limited="true" range="-6.2 6.2" damping="8" frictionloss="1" />
                                        <body quat="0.707107 0 0.707107 0" name="righttube">
                                            <geom type="mesh" mesh="PROXIMAL_TUBE" name="righttube_mesh" rgba="0.2 0.2 0.2 1" />
                                        </body>
                                        <body pos="0 0 0.0486304" quat="0.5 -0.5 -0.5 0.5" name="drive4">
                                            <geom type="mesh" mesh="MK4_LT" name="drive4_mesh" rgba="0.2 0.2 0.2 1" />
                                        </body>
                                        <body name="rightforearm" pos="0.06758 0 0.0486304" quat="0.707107 0 -0.707107 0">
                                            <joint name="joint4" type="hinge" pos="0 0 0" axis="0 0 -1" limited="true" range="-3.14159 1.0" damping="8" frictionloss="1" />
                                            <geom type="mesh" mesh="FOREARM_BRACKET" name="right_forearm_bracket" rgba="0.2 0.2 0.2 1" />
                                            <body pos="0 -0.17 0.05749" quat="0.707107 -0.707107 0 0" name="drive5">
                                                <geom type="mesh" mesh="A35_DRIVE" name="drive5_mesh" rgba="0.2 0.2 0.2 1" />
                                            </body>
                                            <body name="drive6" pos="0 -0.237262 0.05749" quat="0.707107 0 -0.707107 0">
                                                <joint name="joint5" type="hinge" pos="0 0 0" axis="0 1 0" limited="true" range="-6.2 6.2" damping="0.4" frictionloss="0.01" />
                                                <geom type="mesh" mesh="A35_DRIVE" name="drive6_mesh" rgba="0.2 0.2 0.2 1" />
                                                <body name="rightwrist" pos="0 0 -0.0566728">
                                                    <joint name="joint6" type="hinge" pos="0 0 0" axis="0 0 -1" limited="true" range="-1.5708 1.5708" damping="0.04" frictionloss="0.1" />
                                                    <geom type="mesh" mesh="A35_BRACKET" name="rightwrist_mesh" rgba="0.2 0.2 0.2 1" />
                                                    <body pos="0 -0.05 0.0566728" quat="0.707107 -0.707107 0 0" name="drive7">
                                                        <geom type="mesh" mesh="A35_DRIVE" name="drive7_mesh" rgba="0.2 0.2 0.2 1" />
                                                    </body>
                                                    <body name="drive10" pos="0 -0.086 0.0566728" quat="0.707107 0.707107 0 0">
                                                        <joint name="joint7" type="hinge" pos="0 0 0" axis="0 0 -1" limited="true" range="-6.2 6.2" damping=".08" frictionloss="0.1" />
                                                        <geom type="mesh" mesh="PINCER_HOUSING2" name="drive7_housing_mesh" rgba="0.2 0.2 0.2 1" />
                                                        <site name="right_tool" pos="0 0 0.181" size="0.001" />
                                                        <body name="right_d405_mount" pos="-0.0215 0 0.031" euler="1.5707 -1.5707 0">
                                                            <geom type="mesh" mesh="d405_mount" name="right_d405_mount" rgba="0.9 0.9 0.9 1" />
                                                            <body name="right_d405" euler="1.22 0 0" pos="0 0.01 0.03">
                                                                <geom name="right_d405" type="box" size="0.021 0.021 0.0115" />
                                                                <camera mode="fixed" name="right_hand" />
                                                            </body>
                                                            
                                                            <site name="right_hand_cam" euler="-1.93 0 3.1415" pos="0.01 0 0.03" size="0.001" />
                                                        </body>

                                                        <body name="rightgripper" pos="0 0.0135 0.068553" euler="1.15 -1.5707 0">
                                                            <joint name="rightgripper" type="hinge" axis="0 0 1" limited="true" range="-0.01 1" damping="0.01" frictionloss="0.01" />
                                                            <geom type="mesh" mesh="soft_gripper_thin" name="rightgripper" friction="0.00001" rgba="0.9 0.9 0.9 1" group="1" />
                                                            <body name="right_finger_pad" pos="0.052 0.1 0">
                                                                <geom type="mesh" mesh="FINGER_PAD" name="right_finger_pad" rgba="0.6 0.4 0.2 1" group="1" />
                                                            </body>
                                                        </body>
                                                        <body name="rightgripper2" pos="0 -0.0135 0.068553" euler="1.99 1.5707 0">
                                                            <joint name="rightgripper2" type="hinge" axis="0 0 1" limited="true" range="-0.01 1" damping="0.01" frictionloss="0.01" />
                                                            <geom type="mesh" mesh="soft_gripper_thin" name="rightgripper2" friction="0.00001" rgba="0.9 0.9 0.9 1" group="1" />
                                                            <body name="right_finger_pad2" pos="0.052 0.1 0">
                                                                <geom type="mesh" mesh="FINGER_PAD" name="right_finger_pad2" rgba="0.6 0.4 0.2 1" group="1" />
                                                            </body>
                                                        </body>
                                                    </body>
                                                </body>
                                            </body>
                                        </body>
                                    </body>
                                </body>
                            </body>
                        </body>
                    </body>
                </body>
            </body>
        </body>
    </worldbody>
    <actuator>
        
        <intvelocity name="joint56_vel" joint="joint56" ctrllimited="true" ctrlrange="-0.45 0.45" actrange="-6.2 6.2" kp="5000" forcelimited="true" forcerange="-50 50" />
        <intvelocity name="joint57_vel" joint="joint57" ctrllimited="true" ctrlrange="-0.45 0.45" actrange="-1.5708 1.5708" kp="20000" forcelimited="true" forcerange="-55 55" />

        
        <intvelocity name="joint41_vel" joint="joint41" ctrllimited="true" ctrlrange="-0.45 0.45" actrange="-6.2 6.2" kp="10000" forcelimited="true" forcerange="-15 15" />
        <intvelocity name="joint42_vel" joint="joint42" ctrllimited="true" ctrlrange="-0.45 0.45" actrange="-0.15 3.14159" kp="5000" forcelimited="true" forcerange="-15 15" />
        <intvelocity name="joint43_vel" joint="joint43" ctrllimited="true" ctrlrange="-0.45 0.45" actrange="-6.2 6.2" kp="5000" forcelimited="true" forcerange="-10 10" />
        <intvelocity name="joint44_vel" joint="joint44" ctrllimited="true" ctrlrange="-0.45 0.45" actrange="-3.14159 1.0" kp="1000" forcelimited="true" forcerange="-10 10" />
        
        <intvelocity name="joint45_vel" joint="joint45" ctrllimited="true" ctrlrange="-2 2" actrange="-6.2 6.2" kp="100" forcelimited="true" forcerange="-8 8" />
        <intvelocity name="joint46_vel" joint="joint46" ctrllimited="true" ctrlrange="-2 2" actrange="-1.5708 1.5708" kp="500" forcelimited="true" forcerange="-4 4" />
        <intvelocity name="joint47_vel" joint="joint47" ctrllimited="true" ctrlrange="-3.1 3.1" actrange="-6.2 6.2" kp="50" forcelimited="true" forcerange="-3 3" />
        <intvelocity name="leftgripper_vel" joint="leftgripper" ctrllimited="true" ctrlrange="-0.5 0.5" actrange="-0.01 1" kp="35" forcelimited="true" forcerange="-1 1" />

        
        <intvelocity name="joint1_vel" joint="joint1" ctrllimited="true" ctrlrange="-0.45 0.45" actrange="-6.2 6.2" kp="10000" forcelimited="true" forcerange="-15 15" />
        <intvelocity name="joint2_vel" joint="joint2" ctrllimited="true" ctrlrange="-0.45 0.45" actrange="-3.14159 0.15" kp="5000" forcelimited="true" forcerange="-15 15" />
        <intvelocity name="joint3_vel" joint="joint3" ctrllimited="true" ctrlrange="-0.45 0.45" actrange="-6.2 6.2" kp="5000" forcelimited="true" forcerange="-10 10" />
        <intvelocity name="joint4_vel" joint="joint4" ctrllimited="true" ctrlrange="-0.45 0.45" actrange="-3.14159 1.0" kp="1000" forcelimited="true" forcerange="-8 8" />
        
        <intvelocity name="joint5_vel" joint="joint5" ctrllimited="true" ctrlrange="-2 2" actrange="-6.2 6.2" kp="100" forcelimited="true" forcerange="-8 8" />
        <intvelocity name="joint6_vel" joint="joint6" ctrllimited="true" ctrlrange="-2 2" actrange="-1.5708 1.5708" kp="500" forcelimited="true" forcerange="-4 4" />
        <intvelocity name="joint7_vel" joint="joint7" ctrllimited="true" ctrlrange="-3.1 3.1" actrange="-6.2 6.2" kp="50" forcelimited="true" forcerange="-3 3" />
        <intvelocity name="rightgripper_vel" joint="rightgripper" ctrllimited="true" ctrlrange="-0.5 0.5" actrange="-0.01 1" kp="35" forcelimited="true" forcerange="-1 1" />
    </actuator>
    <equality>
        <joint name="left_mimic" joint1="leftgripper" joint2="leftgripper2" solref="0.01 1" />
        <joint name="right_mimic" joint1="rightgripper" joint2="rightgripper2" solref="0.01 1" />
    </equality>
<worldbody>
        <body pos="0 0 0" name="cc_sphere">
            
            <geom type="sphere" name="cc_sphere" size="0.005" rgba="1 1 1 0.1" />
            <joint type="free" name="cc_sphere" damping="0.1" />
        </body>
    </worldbody>
<worldbody>
        <body pos="0 0 -0.445" name="floor">
            <geom type="plane" name="floor" size="50 50 0.1" material="cream-plaster" />
        </body>
    </worldbody>
<worldbody>
        <body name="obstacles" pos="0 0.7 -0.6" euler="0 0 4.7123">
            <body name="wall">
                <geom type="box" name="wall" size="0.05 1 1" pos="0 0 1" material="cream-plaster" />
            </body>
            <light mode="fixed" pos="0.3 0.2 1.7" dir="-0.25 0.1 -1" diffuse="0.61 0.61 0.6" castshadow="false" />
            <light mode="fixed" pos="0.3 -0.2 1.7" dir="-0.25 -0.1 -1" diffuse="0.61 0.61 0.6" castshadow="false" />
            <body name="attach1" pos="0.05 0.75 1.5">
                <geom name="attach1" size="0.02 0.02 0.02" rgba="1.0 0 0 1" />
                <body name="cover">
                    <geom name="cover" class="visual" type="box" size="0.05 0.05 0.05" rgba="1 0 0 1" />
                </body>
            </body>
            <body name="attach2" pos="0.05 -0.55 1">
                <geom name="attach2" type="sphere" size="0.02" rgba="1.0 0 0 1" />
                <body name="goal">
                    <geom name="goal" class="visual" type="sphere" size="0.05" rgba="1 0 1 0.3" />
                </body>
            </body>
            <body name="loop1" pos="0.07 0.31971155934176043 0.8128294992697569">
                <geom type="box" name="loop1_bottom" pos="0.04 0 0" size="0.06 0.01 0.01" rgba="0.5 0.5 1.0 1" />
                <geom type="box" name="loop1_front" pos="0.09 0 0.03" size="0.01 0.01 0.04" rgba="0.5 0.5 1.0 1" />
                <geom type="box" name="loop1_top" pos="0.04 0 0.08" size="0.06 0.01 0.01" rgba="0.5 0.5 1.0 1" />
            </body>
            <body name="loop2" pos="0.07 0.023096654324402374 1.1133202908413151">
                <geom type="box" name="loop2_bottom" pos="0.04 0 0" size="0.06 0.01 0.01" rgba="0.5 0.5 1.0 1" />
                <geom type="box" name="loop2_front" pos="0.09 0 0.03" size="0.01 0.01 0.04" rgba="0.5 0.5 1.0 1" />
                <geom type="box" name="loop2_top" pos="0.04 0 0.08" size="0.06 0.01 0.01" rgba="0.5 0.5 1.0 1" />
            </body>
            <body name="loop3" pos="0.07 -0.3581532610872666 1.00464961069334">
                <geom type="box" name="loop3_bottom" pos="0.04 0 0" size="0.06 0.01 0.01" rgba="0.5 0.5 1.0 1" />
                <geom type="box" name="loop3_front" pos="0.09 0 0.04" size="0.01 0.01 0.04" rgba="0.5 0.5 1.0 1" />
                <geom type="box" name="loop3_top" pos="0.04 0 0.08" size="0.06 0.01 0.01" rgba="0.5 0.5 1.0 1" />
            </body>
        </body>
    </worldbody>
<worldbody>
        <body pos="1.1 0.25 0.55" euler="0 0 -1.5707" name="rope">
            <inertial pos="0 0 0" quat="1 0 0 0" mass="0.1" diaginertia="0.001 0.001 0.001" />
            <composite type="cable" curve="s" count="12 1 1" size="2.0 0.22 1">
                <joint kind="main" damping=".25" stiffness="1" />
                <geom type="capsule" size=".01" rgba=".8 .2 .1 1" condim="1" group="1" />
            </composite>
            <joint type="free" />
        </body>
    </worldbody>
</mujoco>